Traceback (most recent call last):
  File "/scicore/home/weder/GROUP/Innovation/05_job_adds_data/jpap-venv/lib/python3.9/site-packages/pandas/core/indexes/base.py", line 3803, in get_loc
    return self._engine.get_loc(casted_key)
  File "pandas/_libs/index.pyx", line 138, in pandas._libs.index.IndexEngine.get_loc
  File "pandas/_libs/index.pyx", line 165, in pandas._libs.index.IndexEngine.get_loc
  File "pandas/_libs/hashtable_class_helper.pxi", line 2263, in pandas._libs.hashtable.Int64HashTable.get_item
  File "pandas/_libs/hashtable_class_helper.pxi", line 2273, in pandas._libs.hashtable.Int64HashTable.get_item
KeyError: 3

The above exception was the direct cause of the following exception:

Traceback (most recent call last):
  File "/scicore/home/weder/GROUP/Innovation/05_job_adds_data/jpap/scripts/ipl/ipl_dat.py", line 163, in <module>
    create_training_dataset(con = JPOD_CON, save = True, peak=True, use_zsc = True)
  File "/scicore/home/weder/GROUP/Innovation/05_job_adds_data/jpap/scripts/ipl/ipl_dat.py", line 148, in create_training_dataset
    employer_descriptions = _extract_employer_description(df = employer_postings, zsc = use_zsc)
  File "/scicore/home/weder/GROUP/Innovation/05_job_adds_data/jpap/scripts/ipl/ipl_dat.py", line 96, in _extract_employer_description
    extractor.sentences_by_name(employer_names = df["company_name"])
  File "/scicore/home/weder/GROUP/Innovation/05_job_adds_data/jpap/jpap/ipl/DescExtractor.py", line 67, in sentences_by_name
    employer_desc = " ".join([s for s in t if employer_names[i] in s.lower()])
  File "/scicore/home/weder/GROUP/Innovation/05_job_adds_data/jpap/jpap/ipl/DescExtractor.py", line 67, in <listcomp>
    employer_desc = " ".join([s for s in t if employer_names[i] in s.lower()])
  File "/scicore/home/weder/GROUP/Innovation/05_job_adds_data/jpap-venv/lib/python3.9/site-packages/pandas/core/series.py", line 981, in __getitem__
    return self._get_value(key)
  File "/scicore/home/weder/GROUP/Innovation/05_job_adds_data/jpap-venv/lib/python3.9/site-packages/pandas/core/series.py", line 1089, in _get_value
    loc = self.index.get_loc(label)
  File "/scicore/home/weder/GROUP/Innovation/05_job_adds_data/jpap-venv/lib/python3.9/site-packages/pandas/core/indexes/base.py", line 3805, in get_loc
    raise KeyError(key) from err
KeyError: 3
